<?xml version="1.0"?>
<!-- !!!!!!!!!!!!!!!!!!!!!~~~~~~~Left Arm~~~~~~!!!!!!!!!!!!!!!!!!!!!!!!!!! -->
<!-- Author: Devon Ash-->
<!-- Maintainer: noobaca2@gmail.com -->

<!-- TODO: When uprgading our urdf's to be more modular and using xacro, include the transmissions and such -->
 <!-- <xacro:include filename="$(find pr2_description)/urdf/upper_arm_v0/upper_arm.gazebo.xacro" />
  <xacro:include filename="$(find pr2_description)/urdf/upper_arm_v0/upper_arm.transmission.xacro" />
  <xacro:include filename="$(find pr2_description)/urdf/common.xacro" /> -->

<!-- BELOW IS DEPRECATED 

<link name="left_shoulder">
	
	<inertial>
		<mass value="0" />
		<origin xyz="0 0 0" />
		<inertia ixx="0" ixy="0" ixz="0"
			  iyy="0" iyz="0"
			  izz="0" />
	</inertial>
	<collision>
		<origin xyz="0 0 0" rpy="0 0 0" />
		<geometry>
		</geometry>
	</collision>

	<visual>

		<geometry>
			<box size="0.2 0.1 0.22"/>
		</geometry>
		<origin rpy="0 0 0" xyz="0 0 0"/>
		<material name="white">
			<color rgba="1 1 1 1"/>
		</material>
	</visual>

</link>


<joint name="body_to_left_shoulder" type="revolute">

  	<parent link="body"/>
	<child link="left_shoulder"/>
	<origin rpy="0 0 1.57" xyz="-0.25 -0.1 -0.39"/>


	<axis xyz="0 1 0" />

	<limit lower="?" upper="?" effort="?" velocity="${VELOCITY_LIMIT_SCALE*5.5}" /> 

	<calibration falling="${-1.1606 + cal_r_elbow_flex_flag}"/>

	<dynamics damping="?" />

</joint>

 ABOVE IS DEPRECATED -->


<link name="left_upper_arm">

	<!-- TODO: Jordan start -->
	<!-- TODO Jordan: Please fill in the required values specified by "0" or near approximations -->
	<inertial>
		<mass value="0" />
		<origin xyz="0 0 0" />
		<inertia ixx="0" ixy="0" ixz="0"
			  iyy="0" iyz="0"
			  izz="0" />
	</inertial>
        <!-- TODO: Jordan end -->

        <!-- TODO: Someone? Not sure how these are done yet. -->
	<collision>
		<origin xyz="0 0 0" rpy="0 0 0" />
		<geometry>
		  <!-- <mesh filename="package://pr2_description/meshes/upper_arm_v0/elbow_flex.stl" /> -->
		</geometry>
	</collision>

	<visual>
		<geometry>
			<box size="0.47 0.1 0.22"/>
		</geometry>
		<origin rpy="0 0 0" xyz="0 0 0"/>
	
		<!-- TODO: Add meshes -->
		<material name="white">
			<color rgba="1 1 1 1"/>
		</material>
	</visual>


</link>

<joint name="shoulder_to_upper_arm" type="revolute">

        <!-- Note: Crude approximation of the joint, this is not the exact connecting joint location -->
  	<parent link="left_shoulder"/>
	<child link="left_upper_arm"/>
	<origin rpy="0 0 1.57" xyz="0 0.235 0"/>

	<!-- Note: Code template taken from PR2_upper_arm.urdf for templating -->
	<!-- Doc: axis of revolution -->
	<!-- TODO Jordan Start -->
	<!-- TODO Jordan: Please fill in the required values specified by "0" or near approximations -->
	<axis xyz="0 1 0" />
	<!-- TODO Jordan: lower rotation degree w.r.t specified axis, same thing for upper. Effort is max force in newtons. Velocity is max velocity of joint. -->
	<limit lower="?" upper="?" effort="?" velocity="?" /> 

        <!-- Note: PR2 Has safety controller, not sure what it's for yet or what the values do-->
	<!-- <safety_controller k_position="100" k_velocity="3" soft_lower_limit="${-2.3213+0.2}" soft_upper_limit="${0.00-0.15}" /> -->

        <!-- Note: Jordan, do you know what this could be? -->
	<calibration falling="0"/>

        <!-- TODO: Jordan -->
	<dynamics damping="?" />
        <!-- TODO: Jordan end -->

</joint>


 <link name="left_elbow">

  
        <!-- TODO: Jordan start -->
	<!-- TODO Jordan: Please fill in the required values specified by "0" or near approximations -->
	<inertial>
		<mass value="0" />
		<origin xyz="0 0 0" />
		<inertia ixx="0" ixy="0" ixz="0"
			  iyy="0" iyz="0"
			  izz="0" />
	</inertial>
        <!-- TODO: Jordan end -->

        <!-- TODO: Someone? Not sure how these are done yet. -->
	<collision>
		<origin xyz="0 0 0" rpy="0 0 0" />
		<geometry>
		  <!-- <mesh filename="package://pr2_description/meshes/upper_arm_v0/elbow_flex.stl" /> -->
		</geometry>
	</collision>
      

        <!-- Note: Crude approximation of the model, this is not the exact connecting joint location -->
	<visual>
		<geometry>
			<box size="0.18 0.1 0.22"/>
		</geometry>
		<origin rpy="0 0 0" xyz="0 0 0"/>
		<!-- TODO: Add meshes -->
		<material name="black"> 
			<color rgba="0 0 0 1"/>
		</material> 
	</visual>


  </link>

<joint name="upper_arm_to_elbow" type="revolute">

	<!-- Note: Crude approximation of the joint, this is not the exact connecting joint location -->
	<parent link="left_upper_arm"/>
	<child link="left_elbow"/>
	<origin rpy="0 0 0" xyz="0.325 0 0"/>

        <!-- TODO Jordan Start: -->
        <!-- TODO Jordan: Please fill in the required values specified by "?" or near approximations -->
	<!-- Note: Code template taken from PR2_upper_arm.urdf for templating -->
	<!-- Doc: axis of revolution -->
	<axis xyz="0 1 0" />

	<!-- TODO Jordan: lower rotation degree w.r.t specified axis, same thing for upper. Effort is max force in newtons. Velocity is max velocity of joint. -->
	<limit lower="?" upper="?" effort="?" velocity="${VELOCITY_LIMIT_SCALE*5.5}" /> 

        <!-- Note: PR2 Has safety controller, not sure what it's for yet or what the values do-->
	<!-- <safety_controller k_position="100" k_velocity="3" soft_lower_limit="${-2.3213+0.2}" soft_upper_limit="${0.00-0.15}" /> -->

        <!-- Note: Jordan, do you know what this could be? -->
	<calibration falling="${-1.1606 + cal_r_elbow_flex_flag}"/>

        <!-- TODO: Jordan do you know what goes here? I'm not sure-->
	<dynamics damping="?" />
        <!-- TODO: Jordan end: -->

</joint>
