<?xml version="1.0" ?>
<!-- =================================================================================== -->
<!-- |    This document was autogenerated by xacro from talos_base.urdf.xacro          | -->
<!-- |    EDITING THIS FILE BY HAND IS NOT RECOMMENDED                                 | -->
<!-- =================================================================================== -->
<robot name="talos" xmlns:controller="http://playerstage.sourceforge.net/gazebo/xmlschema/#controller" xmlns:interface="http://playerstage.sourceforge.net/gazebo/xmlschema/#interface" xmlns:sensor="http://playerstage.sourceforge.net/gazebo/xmlschema/#sensor" xmlns:xacro="http://ros.org/wiki/xacro">
  <!-- base laser -->
  <!-- drive wheel distance from right edge: 73mm
       drive wheel distance from back edge: 100mm
       drive wheel distance from bottom: 40mm -->
  <!-- simplified box collision geometry for base -->
  <!-- simplified box collision geometry for planar laser -->
  <gazebo reference="camera_link">
    <sensor:ray name="base_laser">
      <rayCount>640</rayCount>
      <rangeCount>640</rangeCount>
      <laserCount>1</laserCount>
      <origin>0.0 0.0 0.0</origin>
      <displayRays>false</displayRays>
      <minAngle>-129.998394137</minAngle>
      <maxAngle>129.998394137</maxAngle>
      <minRange>0.08</minRange>
      <maxRange>10.0</maxRange>
      <resRange>0.01</resRange>
      <updateRate>20</updateRate>
      <controller:gazebo_ros_laser name="gazebo_ros_base_laser_controller" plugin="libgazebo_ros_laser.so">
        <gaussianNoise>0.005</gaussianNoise>
        <alwaysOn>true</alwaysOn>
        <updateRate>20</updateRate>
        <topicName>scan</topicName>
        <frameName>base_laser</frameName>
        <interface:laser name="gazebo_ros_base_laser_iface"/>
      </controller:gazebo_ros_laser>
    </sensor:ray>
  </gazebo>
  <link name="base_link">
    <visual>
      <geometry>
        <box size="0.6 0.6 0.3"/>
      </geometry>
      <material name="transparent_grey">
        <color rgba="1 0.8 0.8 0.3"/>
      </material>
    </visual>
  </link>
  <link name="base_footprint">
    <inertial>
      <mass value="1.0"/>
      <origin xyz="0 0 0"/>
      <inertia ixx="0.01" ixy="0.0" ixz="0.0" iyy="0.01" iyz="0.0" izz="0.01"/>
    </inertial>
    <visual>
      <origin rpy="0 0 0" xyz="0 0 0"/>
      <geometry>
        <box size="0.01 0.01 0.01"/>
      </geometry>
      <material name="white"/>
    </visual>
    <collision>
      <!-- represent base collision with a simple rectangular model, positioned by base_size_z s.t. top 
             surface of the collision box matches the top surface of the talos base -->
      <origin rpy="0 0 0" xyz="0 0 0"/>
      <geometry>
        <box size="0.001 0.001 0.001 "/>
      </geometry>
    </collision>
  </link>
  <joint name="base_footprint_joint" type="fixed">
    <origin rpy="0 0 0" xyz="0 0 0.135"/>
    <child link="base_link"/>
    <parent link="base_footprint"/>
  </joint>
  <joint name="base_laser_joint" type="fixed">
    <axis xyz="0 1 0"/>
    <origin rpy="0 0 0" xyz="0.3 0 0.15"/>
    <parent link="base_link"/>
    <child link="base_laser_link"/>
  </joint>
  <link name="base_laser_link" type="laser">
    <inertial>
      <mass value="0.001"/>
      <origin rpy="0 0 0" xyz="0 0 0"/>
      <inertia ixx="0.0001" ixy="0" ixz="0" iyy="0.000001" iyz="0" izz="0.0001"/>
    </inertial>
  </link>
  <gazebo reference="base_laser_link">
    <sensor name="base_laser" type="ray">
      <always_on>true</always_on>
      <update_rate>20</update_rate>
      <pose>0 0 0 0 0 0</pose>
      <visualize>false</visualize>
      <ray>
        <scan>
          <horizontal>
            <samples>640</samples>
            <resolution>1</resolution>
            <min_angle>-2.2689</min_angle>
            <max_angle>2.2689</max_angle>
          </horizontal>
        </scan>
        <range>
          <min>0.08</min>
          <max>10.0</max>
          <resolution>0.01</resolution>
        </range>
      </ray>
      <plugin filename="libgazebo_ros_laser.so" name="gazebo_ros_base_laser_controller">
        <gaussianNoise>0.005</gaussianNoise>
        <alwaysOn>true</alwaysOn>
        <updateRate>20</updateRate>
        <topicName>base_scan</topicName>
        <frameName>base_laser_link</frameName>
      </plugin>
    </sensor>
  </gazebo>
  <joint name="fl_caster_rotation_joint" type="continuous">
    <axis xyz="0 0 1"/>
    <limit effort="6.5" velocity="10"/>
    <safety_controller k_velocity="10"/>
    <!--
      <calibration rising="${ref_position}" />
      -->
    <dynamics damping="1.0" friction="0.0"/>
    <origin rpy="0 0 0" xyz="0.25 0.2175 -0.22"/>
    <parent link="base_link"/>
    <child link="fl_caster_rotation_link"/>
  </joint>
  <link name="fl_caster_rotation_link">
    </link>
  <joint name="fl_caster_l_wheel" type="fixed">
    <axis xyz="0 1 0"/>
    <limit effort="7" velocity="15"/>
    <safety_controller k_velocity="10"/>
    <dynamics damping="1.0" friction="0.0"/>
    <origin rpy="0 0 0" xyz="0 0.01 0"/>
    <parent link="fl_caster_rotation_link"/>
    <child link="fl_caster_l_wheel_link"/>
  </joint>
  <link name="fl_caster_l_wheel_link">
    <visual>
      <!--<origin xyz="0 0 0" rpy="${M_PI/2} 0 0"/> -->
      <!-- rotation bc cyl. geom prim has symmetry axis in +x dir -->
      <origin rpy="1.5707963268 0 0"/>
      <!-- rotation bc cyl. geom prim has symmetry axis in +x dir -->
      <geometry>
        <cylinder length="0.0261" radius="0.0525"/>
      </geometry>
      <material name="black">
        <color rgba="0 0 0 1"/>
      </material>
    </visual>
  </link>
  <joint name="fr_caster_rotation_joint" type="continuous">
    <axis xyz="0 0 1"/>
    <limit effort="6.5" velocity="10"/>
    <safety_controller k_velocity="10"/>
    <!--
      <calibration rising="${ref_position}" />
      -->
    <dynamics damping="1.0" friction="0.0"/>
    <origin rpy="0 0 0" xyz="0.25 -0.2175 -0.22"/>
    <parent link="base_link"/>
    <child link="fr_caster_rotation_link"/>
  </joint>
  <link name="fr_caster_rotation_link">
    </link>
  <joint name="fr_caster_l_wheel" type="fixed">
    <axis xyz="0 1 0"/>
    <limit effort="7" velocity="15"/>
    <safety_controller k_velocity="10"/>
    <dynamics damping="1.0" friction="0.0"/>
    <origin rpy="0 0 0" xyz="0 0.01 0"/>
    <parent link="fr_caster_rotation_link"/>
    <child link="fr_caster_l_wheel_link"/>
  </joint>
  <link name="fr_caster_l_wheel_link">
    <visual>
      <!--<origin xyz="0 0 0" rpy="${M_PI/2} 0 0"/> -->
      <!-- rotation bc cyl. geom prim has symmetry axis in +x dir -->
      <origin rpy="1.5707963268 0 0"/>
      <!-- rotation bc cyl. geom prim has symmetry axis in +x dir -->
      <geometry>
        <cylinder length="0.0261" radius="0.0525"/>
      </geometry>
      <material name="black">
        <color rgba="0 0 0 1"/>
      </material>
    </visual>
  </link>
  <joint name="rl_drive_rotation_joint" type="continuous">
    <axis xyz="0 0 1"/>
    <limit effort="6.5" velocity="10"/>
    <safety_controller k_velocity="10"/>
    <!--
      <calibration rising="${ref_position}" />
      -->
    <dynamics damping="1.0" friction="0.0"/>
    <origin rpy="0 0 0" xyz="-0.2 0.227 -0.19"/>
    <parent link="base_link"/>
    <child link="rl_drive_rotation_link"/>
  </joint>
  <link name="rl_drive_rotation_link">
    </link>
  <joint name="rl_drive_l_wheel" type="fixed">
    <axis xyz="0 1 0"/>
    <limit effort="7" velocity="15"/>
    <safety_controller k_velocity="10"/>
    <dynamics damping="1.0" friction="0.0"/>
    <origin rpy="0 0 0" xyz="0 0.01 0"/>
    <parent link="rl_drive_rotation_link"/>
    <child link="rl_drive_l_wheel_link"/>
  </joint>
  <link name="rl_drive_l_wheel_link">
    <visual>
      <!--<origin xyz="0 0 0" rpy="${M_PI/2} 0 0"/> -->
      <!-- rotation bc cyl. geom prim has symmetry axis in +x dir -->
      <origin rpy="1.5707963268 0 0"/>
      <!-- rotation bc cyl. geom prim has symmetry axis in +x dir -->
      <geometry>
        <cylinder length="0.013" radius="0.0789"/>
      </geometry>
      <material name="black">
        <color rgba="0 0 0 1"/>
      </material>
    </visual>
  </link>
  <joint name="rr_drive_rotation_joint" type="continuous">
    <axis xyz="0 0 1"/>
    <limit effort="6.5" velocity="10"/>
    <safety_controller k_velocity="10"/>
    <!--
      <calibration rising="${ref_position}" />
      -->
    <dynamics damping="1.0" friction="0.0"/>
    <origin rpy="0 0 0" xyz="-0.2 -0.227 -0.19"/>
    <parent link="base_link"/>
    <child link="rr_drive_rotation_link"/>
  </joint>
  <link name="rr_drive_rotation_link">
    </link>
  <joint name="rr_drive_l_wheel" type="fixed">
    <axis xyz="0 1 0"/>
    <limit effort="7" velocity="15"/>
    <safety_controller k_velocity="10"/>
    <dynamics damping="1.0" friction="0.0"/>
    <origin rpy="0 0 0" xyz="0 0.01 0"/>
    <parent link="rr_drive_rotation_link"/>
    <child link="rr_drive_l_wheel_link"/>
  </joint>
  <link name="rr_drive_l_wheel_link">
    <visual>
      <!--<origin xyz="0 0 0" rpy="${M_PI/2} 0 0"/> -->
      <!-- rotation bc cyl. geom prim has symmetry axis in +x dir -->
      <origin rpy="1.5707963268 0 0"/>
      <!-- rotation bc cyl. geom prim has symmetry axis in +x dir -->
      <geometry>
        <cylinder length="0.013" radius="0.0789"/>
      </geometry>
      <material name="black">
        <color rgba="0 0 0 1"/>
      </material>
    </visual>
  </link>
</robot>

